<?xml version="1.0"?>
<robot name="alpha_robot">
  
  <!-- 添加世界链接 -->
  <link name="world"/>
  
  <!-- 材质定义 -->
  <material name="alpha_black">
    <color rgba="0.3 0.3 0.3 1"/>
  </material>
  
  <material name="alpha_ee_black">
    <color rgba="0.3 0.3 0.3 1"/>
  </material>
  
  <material name="alpha_standard_jaws_black">
    <color rgba="0.3 0.3 0.3 1"/>
  </material>
  
  <!-- 物理材质定义 -->
  <material name="aluminum">
    <color rgba="0.6 0.6 0.6 1"/>
  </material>
  
  <material name="steel">
    <color rgba="0.4 0.4 0.4 1"/>
  </material>
  
  <!-- 传感器材质 -->
  <material name="sensor_material">
    <color rgba="0.8 0.2 0.2 1"/>
  </material>
  
  <!-- 基座链接 - 使用link_0的真实惯性数据 -->
  <link name="alpha_base_link">
    <inertial>
      <mass value="0.367"/>
      <origin xyz="-0.07347272752043597 -0.006114910081743869 -0.0033133487738419617"/>
      <inertia ixx="0.00010349630769738964" ixy="1.3540203864991837e-05" ixz="-6.35202283328774e-05" 
               iyy="0.0010513913877401092" iyz="2.573127984490461e-06" izz="0.0010582080712667847"/>
    </inertial>
  </link>
  
  <!-- 世界到基座的固定关节 -->
  <joint name="alpha_base_joint" type="fixed">
    <origin rpy="0 0 0" xyz="0 0 0"/>
    <parent link="world"/>
    <child link="alpha_base_link"/>
  </joint>
  
  <!-- M3 Inline 链接 - 使用link_0的真实惯性数据和YAML配置 -->
  <link name="alpha_m3_inline_link">
    <visual>
      <geometry>
        <mesh filename="meshes/M3-INLINE.stl"/>
      </geometry>
      <origin rpy="0 0 0" xyz="0 0 0"/>
      <material name="alpha_black"/>
    </visual>
    <collision>
      <geometry>
        <mesh filename="meshes/M3-INLINE.stl"/>
      </geometry>
      <origin rpy="1.5707963267948966 0 0" xyz="-0.075 0 0"/>
    </collision>
    <inertial>
      <mass value="0.367"/>
      <origin xyz="-0.07347272752043597 -0.006114910081743869 -0.0033133487738419617"/>
      <inertia ixx="0.00010349630769738964" ixy="1.3540203864991837e-05" ixz="-6.35202283328774e-05" 
               iyy="0.0010513913877401092" iyz="2.573127984490461e-06" izz="0.0010582080712667847"/>
    </inertial>
  </link>
  
  <joint name="alpha_base_link_joint" type="fixed">
    <parent link="alpha_base_link"/>
    <child link="alpha_m3_inline_link"/>
    <origin rpy="0 0 0" xyz="0 0 0"/>
  </joint>
  
  <!-- M2-1-1 链接 - 使用link_1的真实惯性数据和YAML配置 -->
  <link name="alpha_m2_1_1_link">
    <visual>
      <geometry>
        <mesh filename="meshes/M2-1-1.stl"/>
      </geometry>
      <origin rpy="0 0 -3.141592653589793" xyz="0 0 0.0135"/>
      <material name="alpha_black"/>
    </visual>
    <collision>
      <geometry>
        <mesh filename="meshes/M2-1-1.stl"/>
      </geometry>
      <origin rpy="0 0 -3.141592653589793" xyz="0 0 0.0135"/>
    </collision>
    <inertial>
      <mass value="0.161"/>
      <origin xyz="-0.012254000000000001 -0.021161999999999997 -0.0001120000000000013"/>
      <inertia ixx="0.00010946899999999999" ixy="-2.9828e-05" ixz="8.079999999999982e-07" 
               iyy="4.3987e-05" iyz="5.439999999999951e-07" izz="0.000122362"/>
    </inertial>
  </link>
  
  <joint name="alpha_axis_e" type="revolute">
    <parent link="alpha_m3_inline_link"/>
    <child link="alpha_m2_1_1_link"/>
    <origin xyz="0 0 0.014"/>
    <axis xyz="0 0 1"/>
    <limit effort="54.36" lower="0.032" upper="6.02" velocity="100000"/>
    <dynamics damping="0.1" friction="0.05"/>
    <calibration rising="0.0" falling="0.0"/>
    <safety_controller k_velocity="10.0" k_position="15.0" soft_lower_limit="0.05" soft_upper_limit="6.0"/>
  </joint>
  
  <!-- M2 Joint 链接 - 使用link_2的真实惯性数据和YAML配置 -->
  <link name="alpha_m2_joint_link">
    <visual>
      <geometry>
        <mesh filename="meshes/M2.stl"/>
      </geometry>
      <origin rpy="0 1.5707963267948966 -1.839434450681946" xyz="0 0 0"/>
      <material name="alpha_black"/>
    </visual>
    <collision>
      <geometry>
        <mesh filename="meshes/M2.stl"/>
      </geometry>
      <origin rpy="0 1.5707963267948966 -1.839434450681946" xyz="0.07520803424462785 3.981279797672773e-05 0"/>
    </collision>
    <inertial>
      <mass value="0.38"/>
      <origin xyz="-0.07714230846655669 9.099999999999991e-05 0.000734"/>
      <inertia ixx="8.2697e-05" ixy="-7.4836e-05" ixz="-1.8660000000000091e-06" 
               iyy="0.0008471479999999999" iyz="-3.170000000000026e-07" izz="0.0008684829999999999"/>
    </inertial>
  </link>
  
  <joint name="alpha_axis_d" type="revolute">
    <parent link="alpha_m2_1_1_link"/>
    <child link="alpha_m2_joint_link"/>
    <origin xyz="-0.02 0 0.033"/>
    <axis xyz="0 1 0"/>
    <limit effort="54.36" lower="0.0174533" upper="3.40339" velocity="100000"/>
    <dynamics damping="0.1" friction="0.05"/>
    <calibration rising="0.0" falling="0.0"/>
    <safety_controller k_velocity="10.0" k_position="15.0" soft_lower_limit="0.03" soft_upper_limit="3.37"/>
  </joint>
  
  <!-- M2-1-2 链接 - 使用link_3的真实惯性数据和YAML配置 -->
  <link name="alpha_m2_1_2_link">
    <visual>
      <geometry>
        <mesh filename="meshes/M2-1-3.stl"/>
      </geometry>
      <origin rpy="0 1.5707963267948966 0" xyz="0 0 0"/>
      <material name="alpha_black"/>
    </visual>
    <collision>
      <geometry>
        <mesh filename="meshes/M2-1-3.stl"/>
      </geometry>
      <origin rpy="0 1.5707963267948966 0" xyz="0.02 -0.0165 0"/>
    </collision>
    <inertial>
      <mass value="0.142"/>
      <origin xyz="-0.008812 -0.00014800000000000102 -0.01666"/>
      <inertia ixx="6.359599999999999e-05" ixy="-8.019999999999987e-07" ixz="2.1363e-05" 
               iyy="7.5158e-05" iyz="3.369999999999979e-07" izz="4.0651e-05"/>
    </inertial>
  </link>
  
  <joint name="alpha_axis_c" type="revolute">
    <parent link="alpha_m2_joint_link"/>
    <child link="alpha_m2_1_2_link"/>
    <origin rpy="0 0 3.14159" xyz="-0.04 0 -0.1453"/>
    <axis xyz="0 1 0"/>
    <limit effort="47.112" lower="0.0174533" upper="3.40339" velocity="100000"/>
    <dynamics damping="0.1" friction="0.05"/>
    <calibration rising="0.0" falling="0.0"/>
    <safety_controller k_velocity="10.0" k_position="15.0" soft_lower_limit="0.03" soft_upper_limit="3.37"/>
  </joint>
  
  <!-- M1 链接 - 使用link_4的真实惯性数据和YAML配置 -->
  <link name="alpha_m1_link">
    <visual>
      <geometry>
        <mesh filename="meshes/RS1-100-101-123.stl"/>
      </geometry>
      <origin rpy="1.5707963267948966 2.0344439357957027 2.5580376090008063" xyz="0 0 -0.033"/>
      <material name="alpha_black"/>
    </visual>
    <collision>
      <geometry>
        <mesh filename="meshes/RS1-100-101-123.stl"/>
      </geometry>
      <origin rpy="0 3.141592653589793 -2.61799898038469" xyz="0 0 -0.08787500000000001"/>
    </collision>
    <inertial>
      <mass value="0.355"/>
      <origin xyz="-3.0e-05 0.079119 0.001482000000000005"/>
      <inertia ixx="0.0006159210000000001" ixy="7.916e-06" ixz="6.70000000000005e-08" 
               iyy="6.2574e-05" iyz="-4.2800000000003443e-07" izz="0.000625307"/>
    </inertial>
  </link>
  
  <joint name="alpha_axis_b" type="revolute">
    <parent link="alpha_m2_1_2_link"/>
    <child link="alpha_m1_link"/>
    <origin rpy="0 0 2.09439" xyz="0.02 0 0.033"/>
    <axis xyz="0 0 -1"/>
    <limit effort="33.069" lower="-100000.0" upper="100000.0" velocity="100000"/>
    <dynamics damping="0.1" friction="0.05"/>
    <calibration rising="0.0" falling="0.0"/>
  </joint>
  
  <!-- 末端执行器基座 - 改进惯性数据 -->
  <link name="alpha_ee_base_link">
    <inertial>
      <mass value="0.05"/>
      <origin xyz="0 0 0"/>
      <inertia ixx="5e-5" ixy="0" ixz="0" iyy="5e-5" iyz="0" izz="5e-5"/>
    </inertial>
  </link>
  
  <joint name="alpha_ee_joint" type="fixed">
    <origin rpy="0 0 0" xyz="0 0 0.09975"/>
    <parent link="alpha_m1_link"/>
    <child link="alpha_ee_base_link"/>
  </joint>
  
  <!-- 推杆 - 改进惯性数据 -->
  <link name="alpha_push_rod">
    <inertial>
      <mass value="0.02"/>
      <origin xyz="0 0 0"/>
      <inertia ixx="1e-5" ixy="0" ixz="0" iyy="1e-5" iyz="0" izz="1e-5"/>
    </inertial>
  </link>
  
  <joint name="alpha_axis_a" type="prismatic">
    <origin rpy="0 0 0" xyz="0 0 0.009"/>
    <parent link="alpha_ee_base_link"/>
    <child link="alpha_push_rod"/>
    <axis xyz="0 0 1"/>
    <limit effort="28.992" lower="0.0013" upper="0.0133" velocity="100000"/>
    <dynamics damping="0.05" friction="0.02"/>
    <calibration rising="0.0" falling="0.0"/>
    <safety_controller k_velocity="5.0" k_position="10.0" soft_lower_limit="0.002" soft_upper_limit="0.012"/>
  </joint>
  
  <!-- 标准夹爪基座 - 改进惯性数据 -->
  <link name="alpha_standard_jaws_base_link">
    <visual>
      <geometry>
        <mesh filename="meshes/end_effectors/RS1-124.stl"/>
      </geometry>
      <material name="alpha_standard_jaws_black"/>
    </visual>
    <inertial>
      <mass value="0.03"/>
      <origin xyz="0 0 0"/>
      <inertia ixx="1e-5" ixy="0" ixz="0" iyy="1e-5" iyz="0" izz="1e-5"/>
    </inertial>
  </link>
  
  <joint name="alpha_standard_jaws_base_joint" type="fixed">
    <origin rpy="0 0 0" xyz="0 0 0"/>
    <parent link="alpha_ee_base_link"/>
    <child link="alpha_standard_jaws_base_link"/>
  </joint>
  
  <!-- 夹爪 130 - 改进惯性数据和YAML配置 -->
  <link name="alpha_standard_jaws_rs1_130_link">
    <visual>
      <geometry>
        <mesh filename="meshes/end_effectors/RS1-130.stl"/>
      </geometry>
      <material name="alpha_standard_jaws_black"/>
      <origin rpy="0.5235936732051036 -1.5707963267948966 -1.5707963267948966" xyz="-0.047249999999999986 0 0"/>
    </visual>
    <collision>
      <geometry>
        <box size="0.012 0.03 0.09"/>
      </geometry>
      <origin rpy="0 0 0" xyz="0.0 -0.008 0.045"/>
    </collision>
    <inertial>
      <mass value="0.02"/>
      <origin xyz="0 -0.008 0.045"/>
      <inertia ixx="1e-5" ixy="0" ixz="0" iyy="1e-5" iyz="0" izz="1e-5"/>
    </inertial>
  </link>
  
  <joint name="alpha_standard_jaws_rs1_130_joint" type="revolute">
    <origin rpy="0 0 0" xyz="0 0.0155 0.0069"/>
    <parent link="alpha_standard_jaws_base_link"/>
    <child link="alpha_standard_jaws_rs1_130_link"/>
    <axis xyz="-1 0 0"/>
    <limit effort="10" lower="0" upper="0.5" velocity="10"/>
    <dynamics damping="0.01" friction="0.005"/>
    <mimic joint="alpha_axis_a" multiplier="51" offset="0"/>
  </joint>
  
  <!-- 夹爪 139 - 改进惯性数据 -->
  <link name="alpha_standard_jaws_rs1_139_link">
    <visual>
      <geometry>
        <mesh filename="meshes/end_effectors/RS1-139.stl"/>
      </geometry>
      <material name="alpha_standard_jaws_black"/>
      <origin rpy="0.5235936732051036 -1.5707963267948966 -1.5707963267948966" xyz="-0.047249999999999986 0 0"/>
    </visual>
    <collision>
      <geometry>
        <box size="0.012 0.03 0.09"/>
      </geometry>
      <origin rpy="0 0 0" xyz="0.0 0.008 0.045"/>
    </collision>
    <inertial>
      <mass value="0.02"/>
      <origin xyz="0 0.008 0.045"/>
      <inertia ixx="1e-5" ixy="0" ixz="0" iyy="1e-5" iyz="0" izz="1e-5"/>
    </inertial>
  </link>
  
  <joint name="alpha_standard_jaws_rs1_139_joint" type="revolute">
    <origin rpy="0 0 0" xyz="0 -0.0155 0.0069"/>
    <parent link="alpha_standard_jaws_base_link"/>
    <child link="alpha_standard_jaws_rs1_139_link"/>
    <axis xyz="1 0 0"/>
    <limit effort="10" lower="0" upper="0.5" velocity="10"/>
    <dynamics damping="0.01" friction="0.005"/>
    <mimic joint="alpha_standard_jaws_rs1_130_joint" multiplier="1" offset="0"/>
  </joint>
  
  <!-- 传感器定义 -->
  <!-- 末端执行器力传感器 -->
  <link name="alpha_force_sensor_link">
    <visual>
      <geometry>
        <cylinder radius="0.005" length="0.002"/>
      </geometry>
      <material name="sensor_material"/>
    </visual>
    <inertial>
      <mass value="0.001"/>
      <origin xyz="0 0 0"/>
      <inertia ixx="1e-6" ixy="0" ixz="0" iyy="1e-6" iyz="0" izz="1e-6"/>
    </inertial>
  </link>
  
  <joint name="alpha_force_sensor_joint" type="fixed">
    <origin rpy="0 0 0" xyz="0 0 0.005"/>
    <parent link="alpha_ee_base_link"/>
    <child link="alpha_force_sensor_link"/>
  </joint>
  
  <!-- 关节编码器传感器（虚拟链接用于传感器数据） -->
  <link name="alpha_joint_sensors_link">
    <inertial>
      <mass value="0.001"/>
      <origin xyz="0 0 0"/>
      <inertia ixx="1e-6" ixy="0" ixz="0" iyy="1e-6" iyz="0" izz="1e-6"/>
    </inertial>
  </link>
  
  <joint name="alpha_joint_sensors_joint" type="fixed">
    <origin rpy="0 0 0" xyz="0 0 0"/>
    <parent link="alpha_base_link"/>
    <child link="alpha_joint_sensors_link"/>
  </joint>
  
  <!-- 接触传感器链接 -->
  <link name="alpha_contact_sensor_130_link">
    <visual>
      <geometry>
        <sphere radius="0.002"/>
      </geometry>
      <material name="sensor_material"/>
    </visual>
    <inertial>
      <mass value="0.001"/>
      <origin xyz="0 0 0"/>
      <inertia ixx="1e-6" ixy="0" ixz="0" iyy="1e-6" iyz="0" izz="1e-6"/>
    </inertial>
  </link>
  
  <joint name="alpha_contact_sensor_130_joint" type="fixed">
    <origin rpy="0 0 0" xyz="0 -0.008 0.09"/>
    <parent link="alpha_standard_jaws_rs1_130_link"/>
    <child link="alpha_contact_sensor_130_link"/>
  </joint>
  
  <link name="alpha_contact_sensor_139_link">
    <visual>
      <geometry>
        <sphere radius="0.002"/>
      </geometry>
      <material name="sensor_material"/>
    </visual>
    <inertial>
      <mass value="0.001"/>
      <origin xyz="0 0 0"/>
      <inertia ixx="1e-6" ixy="0" ixz="0" iyy="1e-6" iyz="0" izz="1e-6"/>
    </inertial>
  </link>
  
  <joint name="alpha_contact_sensor_139_joint" type="fixed">
    <origin rpy="0 0 0" xyz="0 0.008 0.09"/>
    <parent link="alpha_standard_jaws_rs1_139_link"/>
    <child link="alpha_contact_sensor_139_link"/>
  </joint>
  
</robot>
